Workbook

Sheet قائمة الموديلات
A1: بيانات الموديلات (مرجع الملخصات والقوائم المنسدلة).
A2: املأ/راجع التفاصيل لإظهار تقارير احترافية.
A4: اسم الموديل (Code) | B4: الاسم المعروض (Display) | C4: الفئة (رجالي/حريمي/يونيسكس) | D4: النوع (سنيكر/كلاسيك/سبورت…) | E4: SKU Prefix | F4: نطاق المقاسات (CSV) | G4: الألوان المتاحة (CSV) | H4: سعر البيع (Retail) | I4: سعر الجملة (Wholesale) | J4: التكلفة | K4: الوزن (جرام) | L4: المخزن/الرف
A5: HK01
A6: HK02
A7: LK01
A8: MKM
A9: AMA8
A10: SK5
A11: MK04
A12: D2
A13: D4
A14: SK23

Sheet طلبات مُدخَلة
A1: التاريخ | B1: الوقت | C1: رقم الطلب | D1: اسم الموديل | E1: SKU/الكود | F1: اللون | G1: المقاس | H1: الكمية | I1: المحافظة/المدينة | J1: ملاحظات

Sheet ملخص المُدخَل
A1: ملخص المرحلة: طلبات مُدخَلة على النظام
A2: إجمالي الكميات لكل موديل (بدون أرقام الطلبات).
A3: يمكن تحديد تاريخ لتصفية الملخص (اختياري).
A4: التاريخ (اختياري): | C4: اتركه فارغًا لعرض جميع البيانات.
A6: اسم الموديل | B6: إجمالي الكمية
A7: ='قائمة الموديلات'!$A$5 -> 0 | B7: =IF(B4="",SUMIF('طلبات مُدخَلة'!$D:$D, A6, 'طلبات مُدخَلة'!$H:$H),SUMIFS('طلبات مُدخَلة'!$H:$H, 'طلبات مُدخَلة'!$D:$D, A6, 'طلبات مُدخَلة'!$A:$A, B4)) -> 0 | D7: إجمالي المرحلة (كل الموديلات): | E7: =SUM(B6:B1005) -> 0
A8: ='قائمة الموديلات'!$A$6 -> 0 | B8: =IF(B4="",SUMIF('طلبات مُدخَلة'!$D:$D, A7, 'طلبات مُدخَلة'!$H:$H),SUMIFS('طلبات مُدخَلة'!$H:$H, 'طلبات مُدخَلة'!$D:$D, A7, 'طلبات مُدخَلة'!$A:$A, B4)) -> 0
A9: ='قائمة الموديلات'!$A$7 -> 0 | B9: =IF(B4="",SUMIF('طلبات مُدخَلة'!$D:$D, A8, 'طلبات مُدخَلة'!$H:$H),SUMIFS('طلبات مُدخَلة'!$H:$H, 'طلبات مُدخَلة'!$D:$D, A8, 'طلبات مُدخَلة'!$A:$A, B4)) -> 0
A10: ='قائمة الموديلات'!$A$8 -> 0 | B10: =IF(B4="",SUMIF('طلبات مُدخَلة'!$D:$D, A9, 'طلبات مُدخَلة'!$H:$H),SUMIFS('طلبات مُدخَلة'!$H:$H, 'طلبات مُدخَلة'!$D:$D, A9, 'طلبات مُدخَلة'!$A:$A, B4)) -> 0
A11: ='قائمة الموديلات'!$A$9 -> 0 | B11: =IF(B4="",SUMIF('طلبات مُدخَلة'!$D:$D, A10, 'طلبات مُدخَلة'!$H:$H),SUMIFS('طلبات مُدخَلة'!$H:$H, 'طلبات مُدخَلة'!$D:$D, A10, 'طلبات مُدخَلة'!$A:$A, B4)) -> 0
A12: ='قائمة الموديلات'!$A$10 -> 0 | B12: =IF(B4="",SUMIF('طلبات مُدخَلة'!$D:$D, A11, 'طلبات مُدخَلة'!$H:$H),SUMIFS('طلبات مُدخَلة'!$H:$H, 'طلبات مُدخَلة'!$D:$D, A11, 'طلبات مُدخَلة'!$A:$A, B4)) -> 0
A13: ='قائمة الموديلات'!$A$11 -> 0 | B13: =IF(B4="",SUMIF('طلبات مُدخَلة'!$D:$D, A12, 'طلبات مُدخَلة'!$H:$H),SUMIFS('طلبات مُدخَلة'!$H:$H, 'طلبات مُدخَلة'!$D:$D, A12, 'طلبات مُدخَلة'!$A:$A, B4)) -> 0
A14: ='قائمة الموديلات'!$A$12 -> 0 | B14: =IF(B4="",SUMIF('طلبات مُدخَلة'!$D:$D, A13, 'طلبات مُدخَلة'!$H:$H),SUMIFS('طلبات مُدخَلة'!$H:$H, 'طلبات مُدخَلة'!$D:$D, A13, 'طلبات مُدخَلة'!$A:$A, B4)) -> 0
A15: ='قائمة الموديلات'!$A$13 -> 0 | B15: =IF(B4="",SUMIF('طلبات مُدخَلة'!$D:$D, A14, 'طلبات مُدخَلة'!$H:$H),SUMIFS('طلبات مُدخَلة'!$H:$H, 'طلبات مُدخَلة'!$D:$D, A14, 'طلبات مُدخَلة'!$A:$A, B4)) -> 0
A16: ='قائمة الموديلات'!$A$14 -> 0 | B16: =IF(B4="",SUMIF('طلبات مُدخَلة'!$D:$D, A15, 'طلبات مُدخَلة'!$H:$H),SUMIFS('طلبات مُدخَلة'!$H:$H, 'طلبات مُدخَلة'!$D:$D, A15, 'طلبات مُدخَلة'!$A:$A, B4)) -> 0
A17: ='قائمة الموديلات'!$A$15 -> 0 | B17: =IF(B4="",SUMIF('طلبات مُدخَلة'!$D:$D, A16, 'طلبات مُدخَلة'!$H:$H),SUMIFS('طلبات مُدخَلة'!$H:$H, 'طلبات مُدخَلة'!$D:$D, A16, 'طلبات مُدخَلة'!$A:$A, B4)) -> 0
A18: ='قائمة الموديلات'!$A$16 -> 0 | B18: =IF(B4="",SUMIF('طلبات مُدخَلة'!$D:$D, A17, 'طلبات مُدخَلة'!$H:$H),SUMIFS('طلبات مُدخَلة'!$H:$H, 'طلبات مُدخَلة'!$D:$D, A17, 'طلبات مُدخَلة'!$A:$A, B4)) -> 0
A19: ='قائمة الموديلات'!$A$17 -> 0 | B19: =IF(B4="",SUMIF('طلبات مُدخَلة'!$D:$D, A18, 'طلبات مُدخَلة'!$H:$H),SUMIFS('طلبات مُدخَلة'!$H:$H, 'طلبات مُدخَلة'!$D:$D, A18, 'طلبات مُدخَلة'!$A:$A, B4)) -> 0
A20: ='قائمة الموديلات'!$A$18 -> 0 | B20: =IF(B4="",SUMIF('طلبات مُدخَلة'!$D:$D, A19, 'طلبات مُدخَلة'!$H:$H),SUMIFS('طلبات مُدخَلة'!$H:$H, 'طلبات مُدخَلة'!$D:$D, A19, 'طلبات مُدخَلة'!$A:$A, B4)) -> 0
A21: ='قائمة الموديلات'!$A$19 -> 0 | B21: =IF(B4="",SUMIF('طلبات مُدخَلة'!$D:$D, A20, 'طلبات مُدخَلة'!$H:$H),SUMIFS('طلبات مُدخَلة'!$H:$H, 'طلبات مُدخَلة'!$D:$D, A20, 'طلبات مُدخَلة'!$A:$A, B4)) -> 0
A22: ='قائمة الموديلات'!$A$20 -> 0 | B22: =IF(B4="",SUMIF('طلبات مُدخَلة'!$D:$D, A21, 'طلبات مُدخَلة'!$H:$H),SUMIFS('طلبات مُدخَلة'!$H:$H, 'طلبات مُدخَلة'!$D:$D, A21, 'طلبات مُدخَلة'!$A:$A, B4)) -> 0
A23: ='قائمة الموديلات'!$A$21 -> 0 | B23: =IF(B4="",SUMIF('طلبات مُدخَلة'!$D:$D, A22, 'طلبات مُدخَلة'!$H:$H),SUMIFS('طلبات مُدخَلة'!$H:$H, 'طلبات مُدخَلة'!$D:$D, A22, 'طلبات مُدخَلة'!$A:$A, B4)) -> 0
A24: ='قائمة الموديلات'!$A$22 -> 0 | B24: =IF(B4="",SUMIF('طلبات مُدخَلة'!$D:$D, A23, 'طلبات مُدخَلة'!$H:$H),SUMIFS('طلبات مُدخَلة'!$H:$H, 'طلبات مُدخَلة'!$D:$D, A23, 'طلبات مُدخَلة'!$A:$A, B4)) -> 0
A25: ='قائمة الموديلات'!$A$23 -> 0 | B25: =IF(B4="",SUMIF('طلبات مُدخَلة'!$D:$D, A24, 'طلبات مُدخَلة'!$H:$H),SUMIFS('طلبات مُدخَلة'!$H:$H, 'طلبات مُدخَلة'!$D:$D, A24, 'طلبات مُدخَلة'!$A:$A, B4)) -> 0
A26: ='قائمة الموديلات'!$A$24 -> 0 | B26: =IF(B4="",SUMIF('طلبات مُدخَلة'!$D:$D, A25, 'طلبات مُدخَلة'!$H:$H),SUMIFS('طلبات مُدخَلة'!$H:$H, 'طلبات مُدخَلة'!$D:$D, A25, 'طلبات مُدخَلة'!$A:$A, B4)) -> 0
A27: ='قائمة الموديلات'!$A$25 -> 0 | B27: =IF(B4="",SUMIF('طلبات مُدخَلة'!$D:$D, A26, 'طلبات مُدخَلة'!$H:$H),SUMIFS('طلبات مُدخَلة'!$H:$H, 'طلبات مُدخَلة'!$D:$D, A26, 'طلبات مُدخَلة'!$A:$A, B4)) -> 0
A28: ='قائمة الموديلات'!$A$26 -> 0 | B28: =IF(B4="",SUMIF('طلبات مُدخَلة'!$D:$D, A27, 'طلبات مُدخَلة'!$H:$H),SUMIFS('طلبات مُدخَلة'!$H:$H, 'طلبات مُدخَلة'!$D:$D, A27, 'طلبات مُدخَلة'!$A:$A, B4)) -> 0
A29: ='قائمة الموديلات'!$A$27 -> 0 | B29: =IF(B4="",SUMIF('طلبات مُدخَلة'!$D:$D, A28, 'طلبات مُدخَلة'!$H:$H),SUMIFS('طلبات مُدخَلة'!$H:$H, 'طلبات مُدخَلة'!$D:$D, A28, 'طلبات مُدخَلة'!$A:$A, B4)) -> 0
A30: ='قائمة الموديلات'!$A$28 -> 0 | B30: =IF(B4="",SUMIF('طلبات مُدخَلة'!$D:$D, A29, 'طلبات مُدخَلة'!$H:$H),SUMIFS('طلبات مُدخَلة'!$H:$H, 'طلبات مُدخَلة'!$D:$D, A29, 'طلبات مُدخَلة'!$A:$A, B4)) -> 0
A31: ='قائمة الموديلات'!$A$29 -> 0 | B31: =IF(B4="",SUMIF('طلبات مُدخَلة'!$D:$D, A30, 'طلبات مُدخَلة'!$H:$H),SUMIFS('طلبات مُدخَلة'!$H:$H, 'طلبات مُدخَلة'!$D:$D, A30, 'طلبات مُدخَلة'!$A:$A, B4)) -> 0
A32: ='قائمة الموديلات'!$A$30 -> 0 | B32: =IF(B4="",SUMIF('طلبات مُدخَلة'!$D:$D, A31, 'طلبات مُدخَلة'!$H:$H),SUMIFS('طلبات مُدخَلة'!$H:$H, 'طلبات مُدخَلة'!$D:$D, A31, 'طلبات مُدخَلة'!$A:$A, B4)) -> 0
A33: ='قائمة الموديلات'!$A$31 -> 0 | B33: =IF(B4="",SUMIF('طلبات مُدخَلة'!$D:$D, A32, 'طلبات مُدخَلة'!$H:$H),SUMIFS('طلبات مُدخَلة'!$H:$H, 'طلبات مُدخَلة'!$D:$D, A32, 'طلبات مُدخَلة'!$A:$A, B4)) -> 0
A34: ='قائمة الموديلات'!$A$32 -> 0 | B34: =IF(B4="",SUMIF('طلبات مُدخَلة'!$D:$D, A33, 'طلبات مُدخَلة'!$H:$H),SUMIFS('طلبات مُدخَلة'!$H:$H, 'طلبات مُدخَلة'!$D:$D, A33, 'طلبات مُدخَلة'!$A:$A, B4)) -> 0
A35: ='قائمة الموديلات'!$A$33 -> 0 | B35: =IF(B4="",SUMIF('طلبات مُدخَلة'!$D:$D, A34, 'طلبات مُدخَلة'!$H:$H),SUMIFS('طلبات مُدخَلة'!$H:$H, 'طلبات مُدخَلة'!$D:$D, A34, 'طلبات مُدخَلة'!$A:$A, B4)) -> 0
A36: ='قائمة الموديلات'!$A$34 -> 0 | B36: =IF(B4="",SUMIF('طلبات مُدخَلة'!$D:$D, A35, 'طلبات مُدخَلة'!$H:$H),SUMIFS('طلبات مُدخَلة'!$H:$H, 'طلبات مُدخَلة'!$D:$D, A35, 'طلبات مُدخَلة'!$A:$A, B4)) -> 0
A37: ='قائمة الموديلات'!$A$35 -> 0 | B37: =IF(B4="",SUMIF('طلبات مُدخَلة'!$D:$D, A36, 'طلبات مُدخَلة'!$H:$H),SUMIFS('طلبات مُدخَلة'!$H:$H, 'طلبات مُدخَلة'!$D:$D, A36, 'طلبات مُدخَلة'!$A:$A, B4)) -> 0
A38: ='قائمة الموديلات'!$A$36 -> 0 | B38: =IF(B4="",SUMIF('طلبات مُدخَلة'!$D:$D, A37, 'طلبات مُدخَلة'!$H:$H),SUMIFS('طلبات مُدخَلة'!$H:$H, 'طلبات مُدخَلة'!$D:$D, A37, 'طلبات مُدخَلة'!$A:$A, B4)) -> 0
A39: ='قائمة الموديلات'!$A$37 -> 0 | B39: =IF(B4="",SUMIF('طلبات مُدخَلة'!$D:$D, A38, 'طلبات مُدخَلة'!$H:$H),SUMIFS('طلبات مُدخَلة'!$H:$H, 'طلبات مُدخَلة'!$D:$D, A38, 'طلبات مُدخَلة'!$A:$A, B4)) -> 0
A40: ='قائمة الموديلات'!$A$38 -> 0 | B40: =IF(B4="",SUMIF('طلبات مُدخَلة'!$D:$D, A39, 'طلبات مُدخَلة'!$H:$H),SUMIFS('طلبات مُدخَلة'!$H:$H, 'طلبات مُدخَلة'!$D:$D, A39, 'طلبات مُدخَلة'!$A:$A, B4)) -> 0
A41: ='قائمة الموديلات'!$A$39 -> 0 | B41: =IF(B4="",SUMIF('طلبات مُدخَلة'!$D:$D, A40, 'طلبات مُدخَلة'!$H:$H),SUMIFS('طلبات مُدخَلة'!$H:$H, 'طلبات مُدخَلة'!$D:$D, A40, 'طلبات مُدخَلة'!$A:$A, B4)) -> 0
...

Sheet طلبات مُؤكَّدة
A1: التاريخ | B1: الوقت | C1: رقم الطلب | D1: اسم الموديل | E1: SKU/الكود | F1: اللون | G1: المقاس | H1: الكمية | I1: المحافظة/المدينة | J1: ملاحظات

Sheet ملخص المُؤكَّد
A1: ملخص المرحلة: طلبات تم تأكيدها تليفونيًا
A2: إجمالي الكميات لكل موديل (بدون أرقام الطلبات).
A3: يمكن تحديد تاريخ لتصفية الملخص (اختياري).
A4: التاريخ (اختياري): | C4: اتركه فارغًا لعرض جميع البيانات.
A6: اسم الموديل | B6: إجمالي الكمية
A7: ='قائمة الموديلات'!$A$5 -> 0 | B7: =IF(B4="",SUMIF('طلبات مُؤكَّدة'!$D:$D, A6, 'طلبات مُؤكَّدة'!$H:$H),SUMIFS('طلبات مُؤكَّدة'!$H:$H, 'طلبات مُؤكَّدة'!$D:$D, A6, 'طلبات مُؤكَّدة'!$A:$A, B4)) -> 0 | D7: إجمالي المرحلة (كل الموديلات): | E7: =SUM(B6:B1005) -> 0
A8: ='قائمة الموديلات'!$A$6 -> 0 | B8: =IF(B4="",SUMIF('طلبات مُؤكَّدة'!$D:$D, A7, 'طلبات مُؤكَّدة'!$H:$H),SUMIFS('طلبات مُؤكَّدة'!$H:$H, 'طلبات مُؤكَّدة'!$D:$D, A7, 'طلبات مُؤكَّدة'!$A:$A, B4)) -> 0
A9: ='قائمة الموديلات'!$A$7 -> 0 | B9: =IF(B4="",SUMIF('طلبات مُؤكَّدة'!$D:$D, A8, 'طلبات مُؤكَّدة'!$H:$H),SUMIFS('طلبات مُؤكَّدة'!$H:$H, 'طلبات مُؤكَّدة'!$D:$D, A8, 'طلبات مُؤكَّدة'!$A:$A, B4)) -> 0
A10: ='قائمة الموديلات'!$A$8 -> 0 | B10: =IF(B4="",SUMIF('طلبات مُؤكَّدة'!$D:$D, A9, 'طلبات مُؤكَّدة'!$H:$H),SUMIFS('طلبات مُؤكَّدة'!$H:$H, 'طلبات مُؤكَّدة'!$D:$D, A9, 'طلبات مُؤكَّدة'!$A:$A, B4)) -> 0
A11: ='قائمة الموديلات'!$A$9 -> 0 | B11: =IF(B4="",SUMIF('طلبات مُؤكَّدة'!$D:$D, A10, 'طلبات مُؤكَّدة'!$H:$H),SUMIFS('طلبات مُؤكَّدة'!$H:$H, 'طلبات مُؤكَّدة'!$D:$D, A10, 'طلبات مُؤكَّدة'!$A:$A, B4)) -> 0
A12: ='قائمة الموديلات'!$A$10 -> 0 | B12: =IF(B4="",SUMIF('طلبات مُؤكَّدة'!$D:$D, A11, 'طلبات مُؤكَّدة'!$H:$H),SUMIFS('طلبات مُؤكَّدة'!$H:$H, 'طلبات مُؤكَّدة'!$D:$D, A11, 'طلبات مُؤكَّدة'!$A:$A, B4)) -> 0
A13: ='قائمة الموديلات'!$A$11 -> 0 | B13: =IF(B4="",SUMIF('طلبات مُؤكَّدة'!$D:$D, A12, 'طلبات مُؤكَّدة'!$H:$H),SUMIFS('طلبات مُؤكَّدة'!$H:$H, 'طلبات مُؤكَّدة'!$D:$D, A12, 'طلبات مُؤكَّدة'!$A:$A, B4)) -> 0
A14: ='قائمة الموديلات'!$A$12 -> 0 | B14: =IF(B4="",SUMIF('طلبات مُؤكَّدة'!$D:$D, A13, 'طلبات مُؤكَّدة'!$H:$H),SUMIFS('طلبات مُؤكَّدة'!$H:$H, 'طلبات مُؤكَّدة'!$D:$D, A13, 'طلبات مُؤكَّدة'!$A:$A, B4)) -> 0
A15: ='قائمة الموديلات'!$A$13 -> 0 | B15: =IF(B4="",SUMIF('طلبات مُؤكَّدة'!$D:$D, A14, 'طلبات مُؤكَّدة'!$H:$H),SUMIFS('طلبات مُؤكَّدة'!$H:$H, 'طلبات مُؤكَّدة'!$D:$D, A14, 'طلبات مُؤكَّدة'!$A:$A, B4)) -> 0
A16: ='قائمة الموديلات'!$A$14 -> 0 | B16: =IF(B4="",SUMIF('طلبات مُؤكَّدة'!$D:$D, A15, 'طلبات مُؤكَّدة'!$H:$H),SUMIFS('طلبات مُؤكَّدة'!$H:$H, 'طلبات مُؤكَّدة'!$D:$D, A15, 'طلبات مُؤكَّدة'!$A:$A, B4)) -> 0
A17: ='قائمة الموديلات'!$A$15 -> 0 | B17: =IF(B4="",SUMIF('طلبات مُؤكَّدة'!$D:$D, A16, 'طلبات مُؤكَّدة'!$H:$H),SUMIFS('طلبات مُؤكَّدة'!$H:$H, 'طلبات مُؤكَّدة'!$D:$D, A16, 'طلبات مُؤكَّدة'!$A:$A, B4)) -> 0
A18: ='قائمة الموديلات'!$A$16 -> 0 | B18: =IF(B4="",SUMIF('طلبات مُؤكَّدة'!$D:$D, A17, 'طلبات مُؤكَّدة'!$H:$H),SUMIFS('طلبات مُؤكَّدة'!$H:$H, 'طلبات مُؤكَّدة'!$D:$D, A17, 'طلبات مُؤكَّدة'!$A:$A, B4)) -> 0
A19: ='قائمة الموديلات'!$A$17 -> 0 | B19: =IF(B4="",SUMIF('طلبات مُؤكَّدة'!$D:$D, A18, 'طلبات مُؤكَّدة'!$H:$H),SUMIFS('طلبات مُؤكَّدة'!$H:$H, 'طلبات مُؤكَّدة'!$D:$D, A18, 'طلبات مُؤكَّدة'!$A:$A, B4)) -> 0
A20: ='قائمة الموديلات'!$A$18 -> 0 | B20: =IF(B4="",SUMIF('طلبات مُؤكَّدة'!$D:$D, A19, 'طلبات مُؤكَّدة'!$H:$H),SUMIFS('طلبات مُؤكَّدة'!$H:$H, 'طلبات مُؤكَّدة'!$D:$D, A19, 'طلبات مُؤكَّدة'!$A:$A, B4)) -> 0
A21: ='قائمة الموديلات'!$A$19 -> 0 | B21: =IF(B4="",SUMIF('طلبات مُؤكَّدة'!$D:$D, A20, 'طلبات مُؤكَّدة'!$H:$H),SUMIFS('طلبات مُؤكَّدة'!$H:$H, 'طلبات مُؤكَّدة'!$D:$D, A20, 'طلبات مُؤكَّدة'!$A:$A, B4)) -> 0
A22: ='قائمة الموديلات'!$A$20 -> 0 | B22: =IF(B4="",SUMIF('طلبات مُؤكَّدة'!$D:$D, A21, 'طلبات مُؤكَّدة'!$H:$H),SUMIFS('طلبات مُؤكَّدة'!$H:$H, 'طلبات مُؤكَّدة'!$D:$D, A21, 'طلبات مُؤكَّدة'!$A:$A, B4)) -> 0
A23: ='قائمة الموديلات'!$A$21 -> 0 | B23: =IF(B4="",SUMIF('طلبات مُؤكَّدة'!$D:$D, A22, 'طلبات مُؤكَّدة'!$H:$H),SUMIFS('طلبات مُؤكَّدة'!$H:$H, 'طلبات مُؤكَّدة'!$D:$D, A22, 'طلبات مُؤكَّدة'!$A:$A, B4)) -> 0
A24: ='قائمة الموديلات'!$A$22 -> 0 | B24: =IF(B4="",SUMIF('طلبات مُؤكَّدة'!$D:$D, A23, 'طلبات مُؤكَّدة'!$H:$H),SUMIFS('طلبات مُؤكَّدة'!$H:$H, 'طلبات مُؤكَّدة'!$D:$D, A23, 'طلبات مُؤكَّدة'!$A:$A, B4)) -> 0
A25: ='قائمة الموديلات'!$A$23 -> 0 | B25: =IF(B4="",SUMIF('طلبات مُؤكَّدة'!$D:$D, A24, 'طلبات مُؤكَّدة'!$H:$H),SUMIFS('طلبات مُؤكَّدة'!$H:$H, 'طلبات مُؤكَّدة'!$D:$D, A24, 'طلبات مُؤكَّدة'!$A:$A, B4)) -> 0
A26: ='قائمة الموديلات'!$A$24 -> 0 | B26: =IF(B4="",SUMIF('طلبات مُؤكَّدة'!$D:$D, A25, 'طلبات مُؤكَّدة'!$H:$H),SUMIFS('طلبات مُؤكَّدة'!$H:$H, 'طلبات مُؤكَّدة'!$D:$D, A25, 'طلبات مُؤكَّدة'!$A:$A, B4)) -> 0
A27: ='قائمة الموديلات'!$A$25 -> 0 | B27: =IF(B4="",SUMIF('طلبات مُؤكَّدة'!$D:$D, A26, 'طلبات مُؤكَّدة'!$H:$H),SUMIFS('طلبات مُؤكَّدة'!$H:$H, 'طلبات مُؤكَّدة'!$D:$D, A26, 'طلبات مُؤكَّدة'!$A:$A, B4)) -> 0
A28: ='قائمة الموديلات'!$A$26 -> 0 | B28: =IF(B4="",SUMIF('طلبات مُؤكَّدة'!$D:$D, A27, 'طلبات مُؤكَّدة'!$H:$H),SUMIFS('طلبات مُؤكَّدة'!$H:$H, 'طلبات مُؤكَّدة'!$D:$D, A27, 'طلبات مُؤكَّدة'!$A:$A, B4)) -> 0
A29: ='قائمة الموديلات'!$A$27 -> 0 | B29: =IF(B4="",SUMIF('طلبات مُؤكَّدة'!$D:$D, A28, 'طلبات مُؤكَّدة'!$H:$H),SUMIFS('طلبات مُؤكَّدة'!$H:$H, 'طلبات مُؤكَّدة'!$D:$D, A28, 'طلبات مُؤكَّدة'!$A:$A, B4)) -> 0
A30: ='قائمة الموديلات'!$A$28 -> 0 | B30: =IF(B4="",SUMIF('طلبات مُؤكَّدة'!$D:$D, A29, 'طلبات مُؤكَّدة'!$H:$H),SUMIFS('طلبات مُؤكَّدة'!$H:$H, 'طلبات مُؤكَّدة'!$D:$D, A29, 'طلبات مُؤكَّدة'!$A:$A, B4)) -> 0
A31: ='قائمة الموديلات'!$A$29 -> 0 | B31: =IF(B4="",SUMIF('طلبات مُؤكَّدة'!$D:$D, A30, 'طلبات مُؤكَّدة'!$H:$H),SUMIFS('طلبات مُؤكَّدة'!$H:$H, 'طلبات مُؤكَّدة'!$D:$D, A30, 'طلبات مُؤكَّدة'!$A:$A, B4)) -> 0
A32: ='قائمة الموديلات'!$A$30 -> 0 | B32: =IF(B4="",SUMIF('طلبات مُؤكَّدة'!$D:$D, A31, 'طلبات مُؤكَّدة'!$H:$H),SUMIFS('طلبات مُؤكَّدة'!$H:$H, 'طلبات مُؤكَّدة'!$D:$D, A31, 'طلبات مُؤكَّدة'!$A:$A, B4)) -> 0
A33: ='قائمة الموديلات'!$A$31 -> 0 | B33: =IF(B4="",SUMIF('طلبات مُؤكَّدة'!$D:$D, A32, 'طلبات مُؤكَّدة'!$H:$H),SUMIFS('طلبات مُؤكَّدة'!$H:$H, 'طلبات مُؤكَّدة'!$D:$D, A32, 'طلبات مُؤكَّدة'!$A:$A, B4)) -> 0
A34: ='قائمة الموديلات'!$A$32 -> 0 | B34: =IF(B4="",SUMIF('طلبات مُؤكَّدة'!$D:$D, A33, 'طلبات مُؤكَّدة'!$H:$H),SUMIFS('طلبات مُؤكَّدة'!$H:$H, 'طلبات مُؤكَّدة'!$D:$D, A33, 'طلبات مُؤكَّدة'!$A:$A, B4)) -> 0
A35: ='قائمة الموديلات'!$A$33 -> 0 | B35: =IF(B4="",SUMIF('طلبات مُؤكَّدة'!$D:$D, A34, 'طلبات مُؤكَّدة'!$H:$H),SUMIFS('طلبات مُؤكَّدة'!$H:$H, 'طلبات مُؤكَّدة'!$D:$D, A34, 'طلبات مُؤكَّدة'!$A:$A, B4)) -> 0
A36: ='قائمة الموديلات'!$A$34 -> 0 | B36: =IF(B4="",SUMIF('طلبات مُؤكَّدة'!$D:$D, A35, 'طلبات مُؤكَّدة'!$H:$H),SUMIFS('طلبات مُؤكَّدة'!$H:$H, 'طلبات مُؤكَّدة'!$D:$D, A35, 'طلبات مُؤكَّدة'!$A:$A, B4)) -> 0
A37: ='قائمة الموديلات'!$A$35 -> 0 | B37: =IF(B4="",SUMIF('طلبات مُؤكَّدة'!$D:$D, A36, 'طلبات مُؤكَّدة'!$H:$H),SUMIFS('طلبات مُؤكَّدة'!$H:$H, 'طلبات مُؤكَّدة'!$D:$D, A36, 'طلبات مُؤكَّدة'!$A:$A, B4)) -> 0
A38: ='قائمة الموديلات'!$A$36 -> 0 | B38: =IF(B4="",SUMIF('طلبات مُؤكَّدة'!$D:$D, A37, 'طلبات مُؤكَّدة'!$H:$H),SUMIFS('طلبات مُؤكَّدة'!$H:$H, 'طلبات مُؤكَّدة'!$D:$D, A37, 'طلبات مُؤكَّدة'!$A:$A, B4)) -> 0
A39: ='قائمة الموديلات'!$A$37 -> 0 | B39: =IF(B4="",SUMIF('طلبات مُؤكَّدة'!$D:$D, A38, 'طلبات مُؤكَّدة'!$H:$H),SUMIFS('طلبات مُؤكَّدة'!$H:$H, 'طلبات مُؤكَّدة'!$D:$D, A38, 'طلبات مُؤكَّدة'!$A:$A, B4)) -> 0
A40: ='قائمة الموديلات'!$A$38 -> 0 | B40: =IF(B4="",SUMIF('طلبات مُؤكَّدة'!$D:$D, A39, 'طلبات مُؤكَّدة'!$H:$H),SUMIFS('طلبات مُؤكَّدة'!$H:$H, 'طلبات مُؤكَّدة'!$D:$D, A39, 'طلبات مُؤكَّدة'!$A:$A, B4)) -> 0
A41: ='قائمة الموديلات'!$A$39 -> 0 | B41: =IF(B4="",SUMIF('طلبات مُؤكَّدة'!$D:$D, A40, 'طلبات مُؤكَّدة'!$H:$H),SUMIFS('طلبات مُؤكَّدة'!$H:$H, 'طلبات مُؤكَّدة'!$D:$D, A40, 'طلبات مُؤكَّدة'!$A:$A, B4)) -> 0
...

Sheet طلبات خارجة للشحن
A1: التاريخ | B1: الوقت | C1: رقم الطلب | D1: اسم الموديل | E1: SKU/الكود | F1: اللون | G1: المقاس | H1: الكمية | I1: المحافظة/المدينة | J1: ملاحظات

Sheet ملخص الخارج
A1: ملخص المرحلة: طلبات خرجت من المخزن للشحن
A2: إجمالي الكميات لكل موديل (بدون أرقام الطلبات).
A3: يمكن تحديد تاريخ لتصفية الملخص (اختياري).
A4: التاريخ (اختياري): | C4: اتركه فارغًا لعرض جميع البيانات.
A6: اسم الموديل | B6: إجمالي الكمية
A7: ='قائمة الموديلات'!$A$5 -> 0 | B7: =IF(B4="",SUMIF('طلبات خارجة للشحن'!$D:$D, A6, 'طلبات خارجة للشحن'!$H:$H),SUMIFS('طلبات خارجة للشحن'!$H:$H, 'طلبات خارجة للشحن'!$D:$D, A6, 'طلبات خارجة للشحن'!$A:$A, B4)) -> 0 | D7: إجمالي المرحلة (كل الموديلات): | E7: =SUM(B6:B1005) -> 0
A8: ='قائمة الموديلات'!$A$6 -> 0 | B8: =IF(B4="",SUMIF('طلبات خارجة للشحن'!$D:$D, A7, 'طلبات خارجة للشحن'!$H:$H),SUMIFS('طلبات خارجة للشحن'!$H:$H, 'طلبات خارجة للشحن'!$D:$D, A7, 'طلبات خارجة للشحن'!$A:$A, B4)) -> 0
A9: ='قائمة الموديلات'!$A$7 -> 0 | B9: =IF(B4="",SUMIF('طلبات خارجة للشحن'!$D:$D, A8, 'طلبات خارجة للشحن'!$H:$H),SUMIFS('طلبات خارجة للشحن'!$H:$H, 'طلبات خارجة للشحن'!$D:$D, A8, 'طلبات خارجة للشحن'!$A:$A, B4)) -> 0
A10: ='قائمة الموديلات'!$A$8 -> 0 | B10: =IF(B4="",SUMIF('طلبات خارجة للشحن'!$D:$D, A9, 'طلبات خارجة للشحن'!$H:$H),SUMIFS('طلبات خارجة للشحن'!$H:$H, 'طلبات خارجة للشحن'!$D:$D, A9, 'طلبات خارجة للشحن'!$A:$A, B4)) -> 0
A11: ='قائمة الموديلات'!$A$9 -> 0 | B11: =IF(B4="",SUMIF('طلبات خارجة للشحن'!$D:$D, A10, 'طلبات خارجة للشحن'!$H:$H),SUMIFS('طلبات خارجة للشحن'!$H:$H, 'طلبات خارجة للشحن'!$D:$D, A10, 'طلبات خارجة للشحن'!$A:$A, B4)) -> 0
A12: ='قائمة الموديلات'!$A$10 -> 0 | B12: =IF(B4="",SUMIF('طلبات خارجة للشحن'!$D:$D, A11, 'طلبات خارجة للشحن'!$H:$H),SUMIFS('طلبات خارجة للشحن'!$H:$H, 'طلبات خارجة للشحن'!$D:$D, A11, 'طلبات خارجة للشحن'!$A:$A, B4)) -> 0
A13: ='قائمة الموديلات'!$A$11 -> 0 | B13: =IF(B4="",SUMIF('طلبات خارجة للشحن'!$D:$D, A12, 'طلبات خارجة للشحن'!$H:$H),SUMIFS('طلبات خارجة للشحن'!$H:$H, 'طلبات خارجة للشحن'!$D:$D, A12, 'طلبات خارجة للشحن'!$A:$A, B4)) -> 0
A14: ='قائمة الموديلات'!$A$12 -> 0 | B14: =IF(B4="",SUMIF('طلبات خارجة للشحن'!$D:$D, A13, 'طلبات خارجة للشحن'!$H:$H),SUMIFS('طلبات خارجة للشحن'!$H:$H, 'طلبات خارجة للشحن'!$D:$D, A13, 'طلبات خارجة للشحن'!$A:$A, B4)) -> 0
A15: ='قائمة الموديلات'!$A$13 -> 0 | B15: =IF(B4="",SUMIF('طلبات خارجة للشحن'!$D:$D, A14, 'طلبات خارجة للشحن'!$H:$H),SUMIFS('طلبات خارجة للشحن'!$H:$H, 'طلبات خارجة للشحن'!$D:$D, A14, 'طلبات خارجة للشحن'!$A:$A, B4)) -> 0
A16: ='قائمة الموديلات'!$A$14 -> 0 | B16: =IF(B4="",SUMIF('طلبات خارجة للشحن'!$D:$D, A15, 'طلبات خارجة للشحن'!$H:$H),SUMIFS('طلبات خارجة للشحن'!$H:$H, 'طلبات خارجة للشحن'!$D:$D, A15, 'طلبات خارجة للشحن'!$A:$A, B4)) -> 0
A17: ='قائمة الموديلات'!$A$15 -> 0 | B17: =IF(B4="",SUMIF('طلبات خارجة للشحن'!$D:$D, A16, 'طلبات خارجة للشحن'!$H:$H),SUMIFS('طلبات خارجة للشحن'!$H:$H, 'طلبات خارجة للشحن'!$D:$D, A16, 'طلبات خارجة للشحن'!$A:$A, B4)) -> 0
A18: ='قائمة الموديلات'!$A$16 -> 0 | B18: =IF(B4="",SUMIF('طلبات خارجة للشحن'!$D:$D, A17, 'طلبات خارجة للشحن'!$H:$H),SUMIFS('طلبات خارجة للشحن'!$H:$H, 'طلبات خارجة للشحن'!$D:$D, A17, 'طلبات خارجة للشحن'!$A:$A, B4)) -> 0
A19: ='قائمة الموديلات'!$A$17 -> 0 | B19: =IF(B4="",SUMIF('طلبات خارجة للشحن'!$D:$D, A18, 'طلبات خارجة للشحن'!$H:$H),SUMIFS('طلبات خارجة للشحن'!$H:$H, 'طلبات خارجة للشحن'!$D:$D, A18, 'طلبات خارجة للشحن'!$A:$A, B4)) -> 0
A20: ='قائمة الموديلات'!$A$18 -> 0 | B20: =IF(B4="",SUMIF('طلبات خارجة للشحن'!$D:$D, A19, 'طلبات خارجة للشحن'!$H:$H),SUMIFS('طلبات خارجة للشحن'!$H:$H, 'طلبات خارجة للشحن'!$D:$D, A19, 'طلبات خارجة للشحن'!$A:$A, B4)) -> 0
A21: ='قائمة الموديلات'!$A$19 -> 0 | B21: =IF(B4="",SUMIF('طلبات خارجة للشحن'!$D:$D, A20, 'طلبات خارجة للشحن'!$H:$H),SUMIFS('طلبات خارجة للشحن'!$H:$H, 'طلبات خارجة للشحن'!$D:$D, A20, 'طلبات خارجة للشحن'!$A:$A, B4)) -> 0
A22: ='قائمة الموديلات'!$A$20 -> 0 | B22: =IF(B4="",SUMIF('طلبات خارجة للشحن'!$D:$D, A21, 'طلبات خارجة للشحن'!$H:$H),SUMIFS('طلبات خارجة للشحن'!$H:$H, 'طلبات خارجة للشحن'!$D:$D, A21, 'طلبات خارجة للشحن'!$A:$A, B4)) -> 0
A23: ='قائمة الموديلات'!$A$21 -> 0 | B23: =IF(B4="",SUMIF('طلبات خارجة للشحن'!$D:$D, A22, 'طلبات خارجة للشحن'!$H:$H),SUMIFS('طلبات خارجة للشحن'!$H:$H, 'طلبات خارجة للشحن'!$D:$D, A22, 'طلبات خارجة للشحن'!$A:$A, B4)) -> 0
A24: ='قائمة الموديلات'!$A$22 -> 0 | B24: =IF(B4="",SUMIF('طلبات خارجة للشحن'!$D:$D, A23, 'طلبات خارجة للشحن'!$H:$H),SUMIFS('طلبات خارجة للشحن'!$H:$H, 'طلبات خارجة للشحن'!$D:$D, A23, 'طلبات خارجة للشحن'!$A:$A, B4)) -> 0
A25: ='قائمة الموديلات'!$A$23 -> 0 | B25: =IF(B4="",SUMIF('طلبات خارجة للشحن'!$D:$D, A24, 'طلبات خارجة للشحن'!$H:$H),SUMIFS('طلبات خارجة للشحن'!$H:$H, 'طلبات خارجة للشحن'!$D:$D, A24, 'طلبات خارجة للشحن'!$A:$A, B4)) -> 0
A26: ='قائمة الموديلات'!$A$24 -> 0 | B26: =IF(B4="",SUMIF('طلبات خارجة للشحن'!$D:$D, A25, 'طلبات خارجة للشحن'!$H:$H),SUMIFS('طلبات خارجة للشحن'!$H:$H, 'طلبات خارجة للشحن'!$D:$D, A25, 'طلبات خارجة للشحن'!$A:$A, B4)) -> 0
A27: ='قائمة الموديلات'!$A$25 -> 0 | B27: =IF(B4="",SUMIF('طلبات خارجة للشحن'!$D:$D, A26, 'طلبات خارجة للشحن'!$H:$H),SUMIFS('طلبات خارجة للشحن'!$H:$H, 'طلبات خارجة للشحن'!$D:$D, A26, 'طلبات خارجة للشحن'!$A:$A, B4)) -> 0
A28: ='قائمة الموديلات'!$A$26 -> 0 | B28: =IF(B4="",SUMIF('طلبات خارجة للشحن'!$D:$D, A27, 'طلبات خارجة للشحن'!$H:$H),SUMIFS('طلبات خارجة للشحن'!$H:$H, 'طلبات خارجة للشحن'!$D:$D, A27, 'طلبات خارجة للشحن'!$A:$A, B4)) -> 0
A29: ='قائمة الموديلات'!$A$27 -> 0 | B29: =IF(B4="",SUMIF('طلبات خارجة للشحن'!$D:$D, A28, 'طلبات خارجة للشحن'!$H:$H),SUMIFS('طلبات خارجة للشحن'!$H:$H, 'طلبات خارجة للشحن'!$D:$D, A28, 'طلبات خارجة للشحن'!$A:$A, B4)) -> 0
A30: ='قائمة الموديلات'!$A$28 -> 0 | B30: =IF(B4="",SUMIF('طلبات خارجة للشحن'!$D:$D, A29, 'طلبات خارجة للشحن'!$H:$H),SUMIFS('طلبات خارجة للشحن'!$H:$H, 'طلبات خارجة للشحن'!$D:$D, A29, 'طلبات خارجة للشحن'!$A:$A, B4)) -> 0
A31: ='قائمة الموديلات'!$A$29 -> 0 | B31: =IF(B4="",SUMIF('طلبات خارجة للشحن'!$D:$D, A30, 'طلبات خارجة للشحن'!$H:$H),SUMIFS('طلبات خارجة للشحن'!$H:$H, 'طلبات خارجة للشحن'!$D:$D, A30, 'طلبات خارجة للشحن'!$A:$A, B4)) -> 0
A32: ='قائمة الموديلات'!$A$30 -> 0 | B32: =IF(B4="",SUMIF('طلبات خارجة للشحن'!$D:$D, A31, 'طلبات خارجة للشحن'!$H:$H),SUMIFS('طلبات خارجة للشحن'!$H:$H, 'طلبات خارجة للشحن'!$D:$D, A31, 'طلبات خارجة للشحن'!$A:$A, B4)) -> 0
A33: ='قائمة الموديلات'!$A$31 -> 0 | B33: =IF(B4="",SUMIF('طلبات خارجة للشحن'!$D:$D, A32, 'طلبات خارجة للشحن'!$H:$H),SUMIFS('طلبات خارجة للشحن'!$H:$H, 'طلبات خارجة للشحن'!$D:$D, A32, 'طلبات خارجة للشحن'!$A:$A, B4)) -> 0
A34: ='قائمة الموديلات'!$A$32 -> 0 | B34: =IF(B4="",SUMIF('طلبات خارجة للشحن'!$D:$D, A33, 'طلبات خارجة للشحن'!$H:$H),SUMIFS('طلبات خارجة للشحن'!$H:$H, 'طلبات خارجة للشحن'!$D:$D, A33, 'طلبات خارجة للشحن'!$A:$A, B4)) -> 0
A35: ='قائمة الموديلات'!$A$33 -> 0 | B35: =IF(B4="",SUMIF('طلبات خارجة للشحن'!$D:$D, A34, 'طلبات خارجة للشحن'!$H:$H),SUMIFS('طلبات خارجة للشحن'!$H:$H, 'طلبات خارجة للشحن'!$D:$D, A34, 'طلبات خارجة للشحن'!$A:$A, B4)) -> 0
A36: ='قائمة الموديلات'!$A$34 -> 0 | B36: =IF(B4="",SUMIF('طلبات خارجة للشحن'!$D:$D, A35, 'طلبات خارجة للشحن'!$H:$H),SUMIFS('طلبات خارجة للشحن'!$H:$H, 'طلبات خارجة للشحن'!$D:$D, A35, 'طلبات خارجة للشحن'!$A:$A, B4)) -> 0
A37: ='قائمة الموديلات'!$A$35 -> 0 | B37: =IF(B4="",SUMIF('طلبات خارجة للشحن'!$D:$D, A36, 'طلبات خارجة للشحن'!$H:$H),SUMIFS('طلبات خارجة للشحن'!$H:$H, 'طلبات خارجة للشحن'!$D:$D, A36, 'طلبات خارجة للشحن'!$A:$A, B4)) -> 0
A38: ='قائمة الموديلات'!$A$36 -> 0 | B38: =IF(B4="",SUMIF('طلبات خارجة للشحن'!$D:$D, A37, 'طلبات خارجة للشحن'!$H:$H),SUMIFS('طلبات خارجة للشحن'!$H:$H, 'طلبات خارجة للشحن'!$D:$D, A37, 'طلبات خارجة للشحن'!$A:$A, B4)) -> 0
A39: ='قائمة الموديلات'!$A$37 -> 0 | B39: =IF(B4="",SUMIF('طلبات خارجة للشحن'!$D:$D, A38, 'طلبات خارجة للشحن'!$H:$H),SUMIFS('طلبات خارجة للشحن'!$H:$H, 'طلبات خارجة للشحن'!$D:$D, A38, 'طلبات خارجة للشحن'!$A:$A, B4)) -> 0
A40: ='قائمة الموديلات'!$A$38 -> 0 | B40: =IF(B4="",SUMIF('طلبات خارجة للشحن'!$D:$D, A39, 'طلبات خارجة للشحن'!$H:$H),SUMIFS('طلبات خارجة للشحن'!$H:$H, 'طلبات خارجة للشحن'!$D:$D, A39, 'طلبات خارجة للشحن'!$A:$A, B4)) -> 0
A41: ='قائمة الموديلات'!$A$39 -> 0 | B41: =IF(B4="",SUMIF('طلبات خارجة للشحن'!$D:$D, A40, 'طلبات خارجة للشحن'!$H:$H),SUMIFS('طلبات خارجة للشحن'!$H:$H, 'طلبات خارجة للشحن'!$D:$D, A40, 'طلبات خارجة للشحن'!$A:$A, B4)) -> 0
...

Sheet تعليمات الاستخدام
A1: قالب التقرير اليومي (مُحدث): إدخال / تأكيد / خروج
A3: خطوات لأ. هبة:
A4: 1) راجعي/كمّلي بيانات 'قائمة الموديلات'.
A5: 2) أدخلي الطلبات في الجداول الثلاثة واختروا الموديل من القائمة المنسدلة.
A6: 3) استخدمي شيتات 'الملخص' لرؤية إجمالي الكمية لكل موديل (مع إمكانية تحديد تاريخ يوم معيّن).
