Workbook

Sheet Cash Cycles
A1: Business ID | B1: Business Name | C1: Order Id | D1: Order Type | E1: Package size | F1: Order Status | G1: Order Reference | H1: Package Description | I1: Customer Name | J1: Customer Phone | K1: Completed At | L1: Confirmed At | M1: Pickup City | N1: Dropoff City | O1: COD | P1: Online Payment Amount | Q1: Shipping Fees | R1: Insurance Fees | S1: Collection Fees | T1: Next Day Transfer Fees | U1: 0 COD Discount | V1: Promotion Discount | W1: POS Fees | X1: COD Fees | Y1: Fulfillment Fees | Z1: VAT | AA1: Bosta Credits | AB1: Opening Package Fees | AC1: Flex Ship Fees | AD1: Flex Ship Amount | AE1: Total Fees | AF1: Net Value | AG1: Payment Status | AH1: Paid At | AI1: Cash-out ID
A2: KqZGUgmoPLcpQWvEtXpQH | B2: mazzboot | C2: 10489208 | D2: SEND | E2: Normal | F2: DELIVERED | G2: now-1049455 | H2: كوتشي رجالي HK02 ابيض 41 - SKU : Mnpr1013-6 - Count: 1 , | I2: ربيع هارون - | J2: +201023040318 | K2: 46000.707 | L2: 46000.939 | M2: El Kalioubia | N2: Aswan | O2: 550 | P2: 0 | Q2: 81.00 | R2: 0.00 | S2: 0.00 | T2: 0.00 | U2: 0.00 | V2: 0.00 | W2: 0.00 | X2: 0.00 | Y2: 0.00 | Z2: 11.34 | AA2: 0 | AB2: 0.00 | AC2: 0.00 | AD2: 0 | AE2: 92.34 | AF2: 457.66 | AG2: Paid | AH2: 46002 | AI2: SUNCOD14DEC25
A3: KqZGUgmoPLcpQWvEtXpQH | B3: mazzboot | C3: 58567677 | D3: SEND | E3: Normal | F3: DELIVERED | G3: now-1050524 | H3: كوتشي حريمي MKF-02 (Nowshoes) رمادي 41 - SKU : mnpr872-15 - Count: 1 , كوتشي حريمي MKF-02 (Nowshoes) ابيض 41 - SKU : mnpr872-10 - Count: 1 , | I3: شروق صبرى - | J3: +201103989220 | K3: 46000.43 | L3: 46000.945 | M3: El Kalioubia | N3: Aswan | O3: 955 | P3: 0 | Q3: 81.00 | R3: 0.00 | S3: 0.00 | T3: 0.00 | U3: 0.00 | V3: 0.00 | W3: 0.00 | X3: 0.00 | Y3: 0.00 | Z3: 11.34 | AA3: 0 | AB3: 0.00 | AC3: 0.00 | AD3: 0 | AE3: 92.34 | AF3: 862.66 | AG3: Paid | AH3: 46002 | AI3: SUNCOD14DEC25
A4: KqZGUgmoPLcpQWvEtXpQH | B4: mazzboot | C4: 44165501 | D4: SEND | E4: Normal | F4: DELIVERED | G4: now-1045740 | H4: كوتشي حريمي MKF-02 (Nowshoes) ابيض 40 - SKU : mnpr872-9 - Count: 1 , | I4: Aya habib - | J4: +201092917420 | K4: 46000.748 | L4: 46000.96 | M4: El Kalioubia | N4: Cairo | O4: 530 | P4: 0 | Q4: 50.00 | R4: 0.00 | S4: 0.00 | T4: 0.00 | U4: 0.00 | V4: 0.00 | W4: 0.00 | X4: 0.00 | Y4: 0.00 | Z4: 7.00 | AA4: 0 | AB4: 0.00 | AC4: 0.00 | AD4: 0 | AE4: 57 | AF4: 473 | AG4: Paid | AH4: 46002 | AI4: SUNCOD14DEC25
A5: KqZGUgmoPLcpQWvEtXpQH | B5: mazzboot | C5: 53832157 | D5: SEND | E5: Normal | F5: DELIVERED | G5: now-1050918 | H5: كوتشي حريمي MKF-02 (Nowshoes) ابيض 37 - SKU : mnpr872-6 - Count: 1 , | I5: هدير حمدي - | J5: +201098537311 | K5: 46000.511 | L5: 46001.323 | M5: El Kalioubia | N5: Sharqia | O5: 530 | P5: 0 | Q5: 60.00 | R5: 0.00 | S5: 0.00 | T5: 0.00 | U5: 0.00 | V5: 0.00 | W5: 0.00 | X5: 0.00 | Y5: 0.00 | Z5: 8.40 | AA5: 0 | AB5: 0.00 | AC5: 0.00 | AD5: 0 | AE5: 68.4 | AF5: 461.6 | AG5: Paid | AH5: 46005 | AI5: SUNCOD14DEC25
A6: KqZGUgmoPLcpQWvEtXpQH | B6: mazzboot | C6: 73892609 | D6: SEND | E6: Normal | F6: DELIVERED | G6: now-1049242 | H6: كوتشي رجالي HK02 ابيض 43 - SKU : Mnpr1013-8 - Count: 1 , | I6: مصطفى محمد - | J6: +201205318081 | K6: 46000.728 | L6: 46001.359 | M6: El Kalioubia | N6: El Kalioubia | O6: 560 | P6: 0 | Q6: 60.00 | R6: 0.00 | S6: 0.00 | T6: 0.00 | U6: 0.00 | V6: 0.00 | W6: 0.00 | X6: 0.00 | Y6: 0.00 | Z6: 8.40 | AA6: 0 | AB6: 0.00 | AC6: 0.00 | AD6: 0 | AE6: 68.4 | AF6: 491.6 | AG6: Paid | AH6: 46005 | AI6: SUNCOD14DEC25
A7: KqZGUgmoPLcpQWvEtXpQH | B7: mazzboot | C7: 30684568 | D7: SEND | E7: Normal | F7: DELIVERED | G7: now-1050037 | H7: كوتشي حريمي MKF-02 (Nowshoes) ابيض 40 - SKU : mnpr872-9 - Count: 1 , | I7: هاله خيرى - | J7: +201010624191 | K7: 46000.609 | L7: 46001.403 | M7: El Kalioubia | N7: Gharbia | O7: 550 | P7: 0 | Q7: 60.00 | R7: 0.00 | S7: 0.00 | T7: 0.00 | U7: 0.00 | V7: 0.00 | W7: 0.00 | X7: 0.00 | Y7: 0.00 | Z7: 8.40 | AA7: 0 | AB7: 0.00 | AC7: 0.00 | AD7: 0 | AE7: 68.4 | AF7: 481.6 | AG7: Paid | AH7: 46005 | AI7: SUNCOD14DEC25
A8: KqZGUgmoPLcpQWvEtXpQH | B8: mazzboot | C8: 53857391 | D8: SEND | E8: Normal | F8: DELIVERED | G8: now-1051839 | H8: كوتشي رجالي HK02 ابيض 42 - SKU : Mnpr1013-7 - Count: 1 , | I8: مصطفي محي - | J8: +201142840763 | K8: 46001.41 | L8: 46001.558 | M8: El Kalioubia | N8: Menya | O8: 600 | P8: 0 | Q8: 71.00 | R8: 0.00 | S8: 0.00 | T8: 0.00 | U8: 0.00 | V8: 0.00 | W8: 0.00 | X8: 0.00 | Y8: 0.00 | Z8: 9.94 | AA8: 0 | AB8: 0.00 | AC8: 0.00 | AD8: 0 | AE8: 80.94 | AF8: 519.06 | AG8: Paid | AH8: 46005 | AI8: SUNCOD14DEC25
A9: KqZGUgmoPLcpQWvEtXpQH | B9: mazzboot | C9: 59481012 | D9: SEND | E9: Normal | F9: DELIVERED | G9: now-1051831 | H9: كوتشي رجالي HK02 ابيض 45 - SKU : Mnpr1013-10 - Count: 1 , | I9: عبدالرحمن صبري - | J9: +201097081483 | K9: 46001.42 | L9: 46001.587 | M9: El Kalioubia | N9: Giza | O9: 575 | P9: 0 | Q9: 50.00 | R9: 0.00 | S9: 0.00 | T9: 0.00 | U9: 0.00 | V9: 0.00 | W9: 0.00 | X9: 0.00 | Y9: 0.00 | Z9: 7.00 | AA9: 0 | AB9: 0.00 | AC9: 0.00 | AD9: 0 | AE9: 57 | AF9: 518 | AG9: Paid | AH9: 46005 | AI9: SUNCOD14DEC25
A10: KqZGUgmoPLcpQWvEtXpQH | B10: mazzboot | C10: 17792494 | D10: SEND | E10: Normal | F10: DELIVERED | G10: now-1051561 | H10: كوتشي حريمي MKF-02 (Nowshoes) رمادي 37 - SKU : mnpr872-11 - Count: 1 , | I10: دينا محمد عبد الرزاق - | J10: +201069406767 | K10: 46001.573 | L10: 46001.616 | M10: El Kalioubia | N10: Alexandria | O10: 430 | P10: 0 | Q10: 54.00 | R10: 0.00 | S10: 0.00 | T10: 0.00 | U10: 0.00 | V10: 0.00 | W10: 0.00 | X10: 0.00 | Y10: 0.00 | Z10: 7.56 | AA10: 0 | AB10: 0.00 | AC10: 0.00 | AD10: 0 | AE10: 61.56 | AF10: 368.44 | AG10: Paid | AH10: 46005 | AI10: SUNCOD14DEC25
A11: KqZGUgmoPLcpQWvEtXpQH | B11: mazzboot | C11: 3643766 | D11: SEND | E11: Normal | F11: DELIVERED | G11: now-1051924 | H11: كوتشي رجالي HK02 ابيض 45 - SKU : Mnpr1013-10 - Count: 1 , | I11: اسلام عكاشه - | J11: +201067753106 | K11: 46001.57 | L11: 46001.628 | M11: El Kalioubia | N11: Cairo | O11: 575 | P11: 0 | Q11: 50.00 | R11: 0.00 | S11: 0.00 | T11: 0.00 | U11: 0.00 | V11: 0.00 | W11: 0.00 | X11: 0.00 | Y11: 0.00 | Z11: 7.00 | AA11: 0 | AB11: 0.00 | AC11: 0.00 | AD11: 0 | AE11: 57 | AF11: 518 | AG11: Paid | AH11: 46005 | AI11: SUNCOD14DEC25
A12: KqZGUgmoPLcpQWvEtXpQH | B12: mazzboot | C12: 43233773 | D12: SEND | E12: Normal | F12: DELIVERED | G12: now-1052545 | H12: كوتشي رجالي HK02 الاسود 44 - SKU : Mnpr1013-4 - Count: 1 , | I12: محمد احمد - | J12: +201124776737 | K12: 46001.625 | L12: 46001.645 | M12: El Kalioubia | N12: Giza | O12: 575 | P12: 0 | Q12: 50.00 | R12: 0.00 | S12: 0.00 | T12: 0.00 | U12: 0.00 | V12: 0.00 | W12: 0.00 | X12: 0.00 | Y12: 0.00 | Z12: 7.00 | AA12: 0 | AB12: 0.00 | AC12: 0.00 | AD12: 0 | AE12: 57 | AF12: 518 | AG12: Paid | AH12: 46005 | AI12: SUNCOD14DEC25
A13: KqZGUgmoPLcpQWvEtXpQH | B13: mazzboot | C13: 74201997 | D13: SEND | E13: Normal | F13: DELIVERED | G13: now-1051938 | H13: كوتشي رجالي HK02 رمادي 45 - SKU : Mnpr1013-15 - Count: 1 , | I13: مصطفي عمر - | J13: +201114591301 | K13: 46001.354 | L13: 46001.645 | M13: El Kalioubia | N13: Cairo | O13: 575 | P13: 0 | Q13: 50.00 | R13: 0.00 | S13: 0.00 | T13: 0.00 | U13: 0.00 | V13: 0.00 | W13: 0.00 | X13: 0.00 | Y13: 0.00 | Z13: 7.00 | AA13: 0 | AB13: 0.00 | AC13: 0.00 | AD13: 0 | AE13: 57 | AF13: 518 | AG13: Paid | AH13: 46005 | AI13: SUNCOD14DEC25
... A63: KqZGUgmoPLcpQWvEtXpQH | B63: mazzboot | C63: 28605608 | D63: SEND | E63: Normal | F63: DELIVERED | G63: now-1051864 | H63: كوتشي رجالي HK02 رمادي 45 - SKU : Mnpr1013-15 - Count: 1 , | I63: محمد سمير - | J63: +201026813577 | K63: 46002.515 | L63: 46002.919 | M63: El Kalioubia | N63: South Sinai | O63: 500 | P63: 0 | Q63: 100.00 | R63: 0.00 | S63: 0.00 | T63: 0.00 | U63: 0.00 | V63: 0.00 | W63: 0.00 | X63: 0.00 | Y63: 0.00 | Z63: 14.00 | AA63: 0 | AB63: 0.00 | AC63: 0.00 | AD63: 0 | AE63: 114 | AF63: 386 | AG63: Paid | AH63: 46005 | AI63: SUNCOD14DEC25

Sheet Sheet1
A1: مودييلات | G1: MKF02 | H1: MK06 | I1: HK02 | L1: قطع تسليم بوسطة من توريد يوم الاحد 14.12.2025
A2: كوتشي رجالي HK02 ابيض 41 - SKU : Mnpr1013-6 - Count: 1 , | B2: 550 | C2: 0 | D2: 81 | E2: 11.34 | I2: 1 | L2: الموديل | M2: عدد القطع | N2: سعر التوريد | O2: استحقاق المصنع
A3: كوتشي حريمي MKF-02 (Nowshoes) رمادي 41 - SKU : mnpr872-15 - Count: 1 , كوتشي حريمي MKF-02 (Nowshoes) ابيض 41 - SKU : mnpr872-10 - Count: 1 , | B3: 955 | C3: 0 | D3: 81 | E3: 11.34 | G3: 2 | L3: MKF02 | M3: =G64 -> 19 | N3: 180 | O3: =M3*N3 -> 3420
A4: كوتشي حريمي MKF-02 (Nowshoes) ابيض 40 - SKU : mnpr872-9 - Count: 1 , | B4: 530 | C4: 0 | D4: 50 | E4: 7 | G4: 1 | L4: MK06 | M4: 6 | N4: 180 | O4: =M4*N4 -> 1080
A5: كوتشي حريمي MKF-02 (Nowshoes) ابيض 37 - SKU : mnpr872-6 - Count: 1 , | B5: 530 | C5: 0 | D5: 60 | E5: 8.4 | G5: 1 | L5: HK02 | M5: 49 | N5: 195 | O5: =M5*N5 -> 9555
A6: كوتشي رجالي HK02 ابيض 43 - SKU : Mnpr1013-8 - Count: 1 , | B6: 560 | C6: 0 | D6: 60 | E6: 8.4 | I6: 1 | M6: =SUM(M3:M5) -> 74 | O6: =SUM(O3:O5) -> 14055
A7: كوتشي حريمي MKF-02 (Nowshoes) ابيض 40 - SKU : mnpr872-9 - Count: 1 , | B7: 550 | C7: 0 | D7: 60 | E7: 8.4 | G7: 1
A8: كوتشي رجالي HK02 ابيض 42 - SKU : Mnpr1013-7 - Count: 1 , | B8: 600 | C8: 0 | D8: 71 | E8: 9.94 | I8: 1
A9: كوتشي رجالي HK02 ابيض 45 - SKU : Mnpr1013-10 - Count: 1 , | B9: 575 | C9: 0 | D9: 50 | E9: 7 | I9: 1
A10: كوتشي حريمي MKF-02 (Nowshoes) رمادي 37 - SKU : mnpr872-11 - Count: 1 , | B10: 430 | C10: 0 | D10: 54 | E10: 7.56 | G10: 1
A11: كوتشي رجالي HK02 ابيض 45 - SKU : Mnpr1013-10 - Count: 1 , | B11: 575 | C11: 0 | D11: 50 | E11: 7 | I11: 1
A12: كوتشي رجالي HK02 الاسود 44 - SKU : Mnpr1013-4 - Count: 1 , | B12: 575 | C12: 0 | D12: 50 | E12: 7 | I12: 1
A13: كوتشي رجالي HK02 رمادي 45 - SKU : Mnpr1013-15 - Count: 1 , | B13: 575 | C13: 0 | D13: 50 | E13: 7 | I13: 1
A14: كوتشي رجالي HK02 ابيض 41 - SKU : Mnpr1013-6 - Count: 1 , | B14: 575 | C14: 0 | D14: 50 | E14: 7 | I14: 1
A15: كوتشي رجالي HK02 ابيض 45 - SKU : Mnpr1013-10 - Count: 1 , | B15: 0 | C15: 575 | D15: 71 | E15: 9.94 | I15: 1
A16: كوتشي حريمي MKF-02 (Nowshoes) ابيض 39 - SKU : mnpr872-8 - Count: 1 , | B16: 530 | C16: 0 | D16: 50 | E16: 7 | G16: 1
A17: كوتشي رجالي HK02 الاسود 44 - SKU : Mnpr1013-4 - Count: 1 , | B17: 510 | C17: 0 | D17: 50 | E17: 7 | I17: 1
A18: كوتشي رجالي HK02 الاسود 45 - SKU : Mnpr1013-5 - Count: 1 , كوتشي رجالي HK02 ابيض 45 - SKU : Mnpr1013-10 - Count: 1 , | B18: 990 | C18: 0 | D18: 50 | E18: 7 | I18: 2
A19: كوتشي حريمي Mk06 (Nowshoes) اسود*بينك 40 - SKU : mnpr871-14 - Count: 1 , | B19: 550 | C19: 0 | D19: 71 | E19: 9.94 | H19: 1
A20: كوتشي رجالي HK02 ابيض 43 - SKU : Mnpr1013-8 - Count: 1 , | B20: 575 | C20: 0 | D20: 50 | E20: 7 | I20: 1
A21: كوتشي حريمي MKF-02 (Nowshoes) الاسود 37 - SKU : mnpr872-1 - Count: 1 , | B21: 550 | C21: 0 | D21: 50 | E21: 7 | G21: 1
A22: كوتشي رجالي HK02 ابيض 41 - SKU : Mnpr1013-6 - Count: 1 , | B22: 575 | C22: 0 | D22: 50 | E22: 7 | I22: 1
A23: كوتشي رجالي HK02 الاسود 42 - SKU : Mnpr1013-2 - Count: 1 , | B23: 575 | C23: 0 | D23: 50 | E23: 7 | I23: 1
A24: كوتشي رجالي HK02 ابيض 43 - SKU : Mnpr1013-8 - Count: 1 , | B24: 560 | C24: 0 | D24: 50 | E24: 7 | I24: 1
A25: كوتشي رجالي HK02 ابيض 45 - SKU : Mnpr1013-10 - Count: 1 , | B25: 575 | C25: 0 | D25: 54 | E25: 7.56 | I25: 1
A26: كوتشي رجالي HK02 ابيض 45 - SKU : Mnpr1013-10 - Count: 1 , | B26: 575 | C26: 0 | D26: 50 | E26: 7 | I26: 1
A27: كوتشي رجالي HK02 ابيض 44 - SKU : Mnpr1013-9 - Count: 1 , | B27: 575 | C27: 0 | D27: 54 | E27: 7.56 | I27: 1
A28: كوتشي رجالي HK02 ابيض 45 - SKU : Mnpr1013-10 - Count: 1 , | B28: 575 | C28: 0 | D28: 50 | E28: 7 | I28: 1
A29: كوتشي رجالي HK02 ابيض 45 - SKU : Mnpr1013-10 - Count: 1 , | B29: 575 | C29: 0 | D29: 54 | E29: 7.56 | I29: 1
A30: كوتشي حريمي MKF-02 (Nowshoes) ابيض 39 - SKU : mnpr872-8 - Count: 1 , | B30: 430 | C30: 0 | D30: 50 | E30: 7 | G30: 1
A31: كوتشي رجالي HK02 الاسود 43 - SKU : Mnpr1013-3 - Count: 1 , | B31: 575 | C31: 0 | D31: 81 | E31: 11.34 | I31: 1
A32: كوتشي رجالي HK02 ابيض 43 - SKU : Mnpr1013-8 - Count: 1 , | B32: 560 | C32: 0 | D32: 50 | E32: 7 | I32: 1
A33: كوتشي حريمي Mk06 (Nowshoes) رمادي 41 - SKU : mnpr871-5 - Count: 1 , كوتشي حريمي Mk06 (Nowshoes) اسود*رمادي 41 - SKU : mnpr871-10 - Count: 1 , | B33: 1035 | C33: 0 | D33: 50 | E33: 7 | H33: 2
A34: كوتشي حريمي Mk06 (Nowshoes) اسود*بينك 41 - SKU : mnpr871-15 - Count: 1 , | B34: 550 | C34: 0 | D34: 50 | E34: 7 | H34: 1
A35: كوتشي رجالي HK02 ابيض 43 - SKU : Mnpr1013-8 - Count: 1 , | B35: 575 | C35: 0 | D35: 50 | E35: 7 | I35: 1
A36: كوتشي حريمي MKF-02 (Nowshoes) ابيض 39 - SKU : mnpr872-8 - Count: 1 , | B36: 550 | C36: 0 | D36: 60 | E36: 8.4 | G36: 1
A37: كوتشي رجالي HK02 ابيض 41 - SKU : Mnpr1013-6 - Count: 1 , | B37: 575 | C37: 0 | D37: 50 | E37: 7 | I37: 1
A38: كوتشي حريمي MKF-02 (Nowshoes) ابيض 38 - SKU : mnpr872-7 - Count: 1 , كوتشي حريمي Mk06 (Nowshoes) اسود*رمادي 38 - SKU : mnpr871-7 - Count: 1 , | B38: 955 | C38: 0 | D38: 60 | E38: 8.4 | G38: 1 | H38: 1
A39: كوتشي رجالي HK02 رمادي 43 - SKU : Mnpr1013-13 - Count: 1 , | B39: 575 | C39: 0 | D39: 60 | E39: 8.4 | I39: 1
A40: كوتشي رجالي HK02 ابيض 41 - SKU : Mnpr1013-6 - Count: 1 , | B40: 575 | C40: 0 | D40: 54 | E40: 7.56 | I40: 1
...

Sheet نهائي
A1: تقفيل تحصيل يوم الاحد 14.12.2025
A2: الموديل | B2: MKF02 | C2: MK06 | D2: HK02
A3: سعر التوريد | B3: 215 | C3: 215 | D3: 235
A4: اجمالي القطع | B4: =Sheet1!G64 -> 19 | C4: =Sheet1!H64 -> 6 | D4: =Sheet1!I64 -> 49
A5: اجمالي المبلغ | B5: =B3*B4 -> 4085 | C5: =C3*C4 -> 1290 | D5: =D3*D4 -> 11515 | E5: =SUM(B5:D5) -> 16890
A7: التحصيل | B7: =Sheet1!B64+Sheet1!C64 -> 38790
A8: المبلغ لقطع التوريد | B8: =E5 -> 16890
A9: إجمالي مصاريف الشحن | B9: =Sheet1!D64+Sheet1!E64 -> 4010.52
A10: إجمالي مصاريف المرتجع | B10: 0
A11: المبلغ المستحق | B11: =B7-B8-B9-B10 -> 17889.48
